Workbook

Sheet Sheet1
A1: Name | B1: ISIN | C1: Annual securities report | D1: Quarterly securities report | E1: Report of Possession of Large Volume | F1: Share Buyback Report | G1: Responsible | H1: Code | I1: EDINET | J1: JPX | K1: Status | L1: Remarks | M1: Last researched date | N1: Share Change? (Y/N) | O1: FF Change? (Y/N) | P1: RIC | Q1: Issued Share (SII) | R1: Data image for Issued share | S1: Treasury share (TS) | T1: Data image for Treasury share | U1: Calculated FF (Approximate) | V1: TR Treasury shares | W1: Treasury Shares% | X1: 4D Shares | Y1: 4D FF | Z1: Treasury blocked | AA1: Treasury changed | AB1: Issue shares changed | AC1: FF changed | AD1: RT image (SII & TS) changed | AE1: New RT dates (SII | TS) | AF1: Last Check | AG1: JPX Report Date | AH1: Expected JPX Report Date | AI1: Python Web Report (JPX) | AJ1: Python Web Report (EDINET) | AK1: 4D_share (Tracking) | AL1: 4D_FF (Tracking) | AM1: Tracking vs RT (Share) | AN1: Tracking vs RT (FF) | AO1: Check1 - share | AP1: Check2- FF
A2: Gunma Bank Ltd. | B2: JP3276400003 | G2: Fred | H2: 8334 | I2: https://disclosure2.edinet-fsa.go.jp/WEEK0020.aspx | J2: https://www2.jpx.co.jp/tseHpFront/StockSearch.do?callJorEFlg=1&method=&topSearchStr=8334 | K2: Done | N2: N | O2: N | P2: 8334.T | Q2: 395888177 | R2: 46022 | S2: 17387774 | T2: 46022 | U2: 1 | V2: 17387774 | W2: 0.0439 | X2: 395888177 | Y2: 1 | AD2: RT - Unchanged | AE2: 31-Dec-2025 | 31-Dec-2025 | AF2: 31-Dec-2025 | 31-Dec-2025 | AG2: 46056.149 | AH2: 46153 | AK2: 395888177 | AL2: 1 | AM2: 0 | AN2: 0
A3: Japan Real Estate Investment C | B3: JP3027680002 | G3: Fred | H3: 8952 | I3: https://disclosure2.edinet-fsa.go.jp/WEEK0020.aspx | J3: https://www2.jpx.co.jp/tseHpFront/StockSearch.do?callJorEFlg=1&method=&topSearchStr=8952 | K3: WIP | P3: 8952.T | Q3: 7283580 | R3: 46136 | S3: 0 | T3: 45930 | U3: 0.95 | V3: 0 | W3: 0 | X3: 7114320 | Y3: 1 | AB3: Y | AC3: Y | AD3: RT - Unchanged | AE3: 24-Apr-2026 | 30-Sep-2025 | AF3: 24-Apr-2026 | 30-Sep-2025 | AG3: NULL | AH3: 46160 | AK3: 7114320 | AL3: 1 | AM3: 0.023238572 | AN3: 0.052631579
A4: Nippon Building Fund Inc. | B4: JP3027670003 | G4: Fred | H4: 8951 | I4: https://disclosure2.edinet-fsa.go.jp/WEEK0020.aspx | J4: https://www2.jpx.co.jp/tseHpFront/StockSearch.do?callJorEFlg=1&method=&topSearchStr=8951 | K4: WIP | P4: 8951.T | Q4: 8815000 | R4: 46048 | S4: 0 | T4: 46022 | U4: 1 | V4: 0 | W4: 0 | X4: 8815000 | Y4: 1 | AD4: RT - Unchanged | AE4: 26-Jan-2026 | 31-Dec-2025 | AF4: 26-Jan-2026 | 31-Dec-2025 | AG4: NULL | AH4: 46251 | AK4: 8815000 | AL4: 1 | AM4: 0 | AN4: 0
A5: Nomura Research Institute Ltd. | B5: JP3762800005 | G5: Fred | H5: 4307 | I5: https://disclosure2.edinet-fsa.go.jp/WEEK0020.aspx | J5: https://www2.jpx.co.jp/tseHpFront/StockSearch.do?callJorEFlg=1&method=&topSearchStr=4307 | K5: Done | N5: N | O5: N | P5: 4307.T | Q5: 581241511 | R5: 46112 | S5: 6837002 | T5: 46112 | U5: 0.8009 | V5: 6837002 | W5: 0.0118 | X5: 581241511 | Y5: 0.8009 | AD5: RT - Unchanged | AE5: 31-Mar-2026 | 31-Mar-2026 | AF5: 31-Mar-2026 | 31-Mar-2026 | AG5: 46136.5 | AH5: 46230 | AK5: 581241511 | AL5: 0.8009 | AM5: 0 | AN5: 0
A6: Glory Ltd. | B6: JP3274400005 | G6: Fred | H6: 6457 | I6: https://disclosure2.edinet-fsa.go.jp/WEEK0020.aspx | J6: https://www2.jpx.co.jp/tseHpFront/StockSearch.do?callJorEFlg=1&method=&topSearchStr=6457 | K6: Done | N6: N | O6: Y | P6: 6457.T | Q6: 58938210 | R6: 46022 | S6: 6853250 | T6: 46142 | U6: 0.8837 | V6: 6548650 | W6: 0.1111 | X6: 58938210 | Y6: 0.8998 | Z6: Y | AA6: Y | AC6: Y | AD6: RT - Unchanged | AE6: 31-Dec-2025 | 30-Apr-2026 | AF6: 31-Dec-2025 | 30-Apr-2026 | AG6: 46059.503 | AH6: 46157 | AK6: 58938210 | AL6: 0.8998 | AM6: 0 | AN6: 0.018218853
A7: MCDONALD'S HOLDINGS | B7: JP3750500005 | G7: Fred | H7: 2702 | I7: https://disclosure2.edinet-fsa.go.jp/WEEK0020.aspx | J7: https://www2.jpx.co.jp/tseHpFront/StockSearch.do?callJorEFlg=1&method=&topSearchStr=2702 | K7: Done | N7: N | O7: N | P7: 2702.T | Q7: 132960000 | R7: 46022 | S7: 1231 | T7: 46022 | U7: 0.6468 | V7: 1231 | W7: 0 | X7: 132960000 | Y7: 0.6468 | AD7: RT - Unchanged | AE7: 31-Dec-2025 | 31-Dec-2025 | AF7: 31-Dec-2025 | 31-Dec-2025 | AG7: 46059.5 | AH7: 46154 | AK7: 132960000 | AL7: 0.6468 | AM7: 0 | AN7: 0
A8: Furukawa Electric Co. Ltd. | B8: JP3827200001 | G8: Fred | H8: 5801 | I8: https://disclosure2.edinet-fsa.go.jp/WEEK0020.aspx | J8: https://www2.jpx.co.jp/tseHpFront/StockSearch.do?callJorEFlg=1&method=&topSearchStr=5801 | K8: Done | N8: N | O8: N | P8: 5801.T | Q8: 70666917 | R8: 46022 | S8: 316933 | T8: 46022 | U8: 1 | V8: 316933 | W8: 0.0045 | X8: 70666917 | Y8: 1 | AD8: RT - Unchanged | AE8: 31-Dec-2025 | 31-Dec-2025 | AF8: 31-Dec-2025 | 31-Dec-2025 | AG8: 46062.438 | AH8: 46154 | AK8: 70666917 | AL8: 1 | AM8: 0 | AN8: 0
A9: FUKUDA DENSHI | B9: JP3806000000 | G9: Fred | H9: 6960 | I9: https://disclosure2.edinet-fsa.go.jp/WEEK0020.aspx | J9: https://www2.jpx.co.jp/tseHpFront/StockSearch.do?callJorEFlg=1&method=&topSearchStr=6960 | K9: Done | N9: N | O9: Y | P9: 6960.T | Q9: 37747300 | R9: 46022 | S9: 10731565 | T9: 46100 | U9: 0.5663 | V9: 10731565 | W9: 0.2843 | X9: 37747300 | Y9: 0.5739 | Z9: Y | AC9: Y | AD9: RT - Unchanged | AE9: 31-Dec-2025 | 19-Mar-2026 | AF9: 31-Dec-2025 | 19-Mar-2026 | AG9: 46048.542 | AH9: 46157 | AK9: 37747300 | AL9: 0.5739 | AM9: 0 | AN9: 0.013420449
A10: Fujitsu Ltd. | B10: JP3818000006 | G10: Fred | H10: 6702 | I10: https://disclosure2.edinet-fsa.go.jp/WEEK0020.aspx | J10: https://www2.jpx.co.jp/tseHpFront/StockSearch.do?callJorEFlg=1&method=&topSearchStr=6702 | K10: Done | N10: N | O10: Y | P10: 6702.T | Q10: 1739778265 | R10: 46112 | S10: 5000060 | T10: 46112 | U10: 1 | V10: 5000060 | W10: 0.0029 | X10: 2071108450 | Y10: 0.8435 | AB10: Y | AC10: Y | AD10: RT - Unchanged | AE10: 31-Mar-2026 | 31-Mar-2026 | AF10: 31-Mar-2026 | 31-Mar-2026 | AG10: 46140.506 | AH10: 46231 | AK10: 2071108450 | AL10: 0.8479 | AM10: 0.19044392 | AN10: 0.1521
A11: Fanuc Ltd. | B11: JP3802400006 | G11: Fred | H11: 6954 | I11: https://disclosure2.edinet-fsa.go.jp/WEEK0020.aspx | J11: https://www2.jpx.co.jp/tseHpFront/StockSearch.do?callJorEFlg=1&method=&topSearchStr=6954 | K11: Done | N11: Y | O11: Y | P11: 6954.T | Q11: 982272430 | R11: 46171 | S11: 49113621 | T11: 46171 | U11: 0.95 | V11: 49113621 | W11: 0.05 | X11: 982383493 | Y11: 0.9499 | Z11: Y | AB11: Y | AC11: Y | AD11: RT - Unchanged | AE11: 29-May-2026 | 29-May-2026 | AF11: 29-May-2026 | 29-May-2026 | AG11: 46136.5 | AH11: 46226 | AK11: 982383493 | AL11: 0.9499 | AM11: 0.00011306741 | AN11: 0.00010526316
A12: FUJI OIL | B12: JP3816400000 | G12: Fred | H12: 2607 | I12: https://disclosure2.edinet-fsa.go.jp/WEEK0020.aspx | J12: https://www2.jpx.co.jp/tseHpFront/StockSearch.do?callJorEFlg=1&method=&topSearchStr=2607 | K12: Done | N12: N | O12: N | P12: 2607.T | Q12: 87569383 | R12: 46022 | S12: 1586816 | T12: 46022 | U12: 0.5814 | V12: 1586816 | W12: 0.0181 | X12: 87569383 | Y12: 0.5814 | AD12: RT - Unchanged | AE12: 31-Dec-2025 | 31-Dec-2025 | AF12: 31-Dec-2025 | 31-Dec-2025 | AG12: 46063.5 | AH12: 46154 | AK12: 87569383 | AL12: 0.5814 | AM12: 0 | AN12: 0
A13: Fujikura Ltd. | B13: JP3811000003 | G13: Fred | H13: 5803 | I13: https://disclosure2.edinet-fsa.go.jp/WEEK0020.aspx | J13: https://www2.jpx.co.jp/tseHpFront/StockSearch.do?callJorEFlg=1&method=&topSearchStr=5803 | K13: Done | N13: N | O13: N | P13: 5803.T | Q13: 1775180526 | R13: 46111 | S13: 119599386 | T13: 46111 | U13: 0.9326 | V13: 119599386 | W13: 0.0674 | X13: 1775180526 | Y13: 0.9326 | Z13: Y | AD13: RT - Unchanged | AE13: 30-Mar-2026 | 30-Mar-2026 | AF13: 30-Mar-2026 | 30-Mar-2026 | AG13: 46062.438 | AH13: 46156 | AK13: 295863421 | AL13: 0.9326 | AM13: 0.83333333 | AN13: 0
A14: H.U. GROUP HOLDINGS INC. | B14: JP3822000000 | G14: Fred | H14: 4544 | I14: https://disclosure2.edinet-fsa.go.jp/WEEK0020.aspx | J14: https://www2.jpx.co.jp/tseHpFront/StockSearch.do?callJorEFlg=1&method=&topSearchStr=4544 | K14: Done | N14: N | O14: N | P14: 4544.T | Q14: 57492322 | R14: 46112 | S14: 2006360 | T14: 46022 | U14: 1 | V14: 2006360 | W14: 0.0349 | X14: 57490722 | Y14: 1 | AB14: Y | AD14: RT - Unchanged | AE14: 31-Mar-2026 | 31-Dec-2025 | AF14: 31-Mar-2026 | 31-Dec-2025 | AG14: 46062.262 | AH14: 46157 | AK14: 57490722 | AL14: 1 | AM14: 2.7829803e-05 | AN14: 0
A15: FUJI | B15: JP3809200003 | G15: Fred | H15: 6134 | I15: https://disclosure2.edinet-fsa.go.jp/WEEK0020.aspx | J15: https://www2.jpx.co.jp/tseHpFront/StockSearch.do?callJorEFlg=1&method=&topSearchStr=6134 | K15: Done | N15: N | O15: N | P15: 6134.T | Q15: 97823748 | R15: 46022 | S15: 9910545 | T15: 46022 | U15: 0.8987 | V15: 9910545 | W15: 0.1013 | X15: 97823748 | Y15: 0.8987 | Z15: Y | AD15: RT - Unchanged | AE15: 31-Dec-2025 | 31-Dec-2025 | AF15: 31-Dec-2025 | 31-Dec-2025 | AG15: 46063.5 | AH15: 46156 | AK15: 97823748 | AL15: 0.8987 | AM15: 0 | AN15: 0
A16: FUJIFILM Holdings Corp. | B16: JP3814000000 | G16: Fred | H16: 4901 | I16: https://disclosure2.edinet-fsa.go.jp/WEEK0020.aspx | J16: https://www2.jpx.co.jp/tseHpFront/StockSearch.do?callJorEFlg=1&method=&topSearchStr=4901 | K16: Done | N16: N | O16: N | P16: 4901.T | Q16: 1243877184 | R16: 46022 | S16: 38580618 | T16: 46022 | U16: 1 | V16: 38580618 | W16: 0.031 | X16: 1243877184 | Y16: 1 | AD16: RT - Unchanged | AE16: 31-Dec-2025 | 31-Dec-2025 | AF16: 31-Dec-2025 | 31-Dec-2025 | AG16: 46058.438 | AH16: 46154 | AK16: 1243877184 | AL16: 1 | AM16: 0 | AN16: 0
A17: SUBARU CORPORATION | B17: JP3814800003 | G17: Fred | H17: 7270 | I17: https://disclosure2.edinet-fsa.go.jp/WEEK0020.aspx | J17: https://www2.jpx.co.jp/tseHpFront/StockSearch.do?callJorEFlg=1&method=&topSearchStr=7270 | K17: Done | N17: N | O17: N | P17: 7270.T | Q17: 717335273 | R17: 46042 | S17: 1906633 | T17: 46042 | U17: 0.7859 | V17: 1906633 | W17: 0.0027 | X17: 717335273 | Y17: 0.7859 | AD17: RT - Unchanged | AE17: 20-Jan-2026 | 20-Jan-2026 | AF17: 20-Jan-2026 | 20-Jan-2026 | AG17: 46058.478 | AH17: 46157 | AI17: 45989 | AK17: 717335273 | AL17: 0.7905 | AM17: 0 | AN17: 0.005853162
A18: FUJI ELECTRIC | B18: JP3820000002 | G18: Fred | H18: 6504 | I18: https://disclosure2.edinet-fsa.go.jp/WEEK0020.aspx | J18: https://www2.jpx.co.jp/tseHpFront/StockSearch.do?callJorEFlg=1&method=&topSearchStr=6504 | K18: Done | N18: N | O18: N | P18: 6504.T | Q18: 149296991 | R18: 46112 | S18: 1900322 | T18: 46112 | U18: 1 | V18: 1900322 | W18: 0.0127 | X18: 149296991 | Y18: 1 | AD18: RT - Unchanged | AE18: 31-Mar-2026 | 31-Mar-2026 | AF18: 31-Mar-2026 | 31-Mar-2026 | AG18: 46140.501 | AH18: 46232 | AK18: 149296991 | AL18: 1 | AM18: 0 | AN18: 0
A19: NORTH PACIFIC BANK | B19: JP3843400007 | G19: Fred | H19: 8524 | I19: https://disclosure2.edinet-fsa.go.jp/WEEK0020.aspx | J19: https://www2.jpx.co.jp/tseHpFront/StockSearch.do?callJorEFlg=1&method=&topSearchStr=8524 | K19: Done | N19: N | O19: Y | P19: 8524.T | Q19: 378060179 | R19: 46022 | S19: 3943019 | T19: 46091 | U19: 0.9385 | V19: 3943019 | W19: 0.0104 | X19: 378060179 | Y19: 0.9417 | AC19: Y | AD19: RT - Unchanged | AE19: 31-Dec-2025 | 10-Mar-2026 | AF19: 31-Dec-2025 | 10-Mar-2026 | AG19: 46063.438 | AH19: 46152 | AK19: 378060179 | AL19: 0.9417 | AM19: 0 | AN19: 0.0034096963
A20: Fast Retailing Co. Ltd. | B20: JP3802300008 | G20: Fred | H20: 9983 | I20: https://disclosure2.edinet-fsa.go.jp/WEEK0020.aspx | J20: https://www2.jpx.co.jp/tseHpFront/StockSearch.do?callJorEFlg=1&method=&topSearchStr=9983 | K20: Done | N20: N | O20: Y | P20: 9983.T | Q20: 318220968 | R20: 46081 | S20: 11381227 | T20: 46081 | U20: 0.7985 | V20: 11381227 | W20: 0.0358 | X20: 318220968 | Y20: 0.788 | AC20: Y | AD20: RT - Unchanged | AE20: 28-Feb-2026 | 28-Feb-2026 | AF20: 28-Feb-2026 | 28-Feb-2026 | AG20: 46121.501 | AH20: 46211 | AK20: 318220968 | AL20: 0.788 | AM20: 0 | AN20: 0.013149656
A21: LINTEC | B21: JP3977200009 | G21: Fred | H21: 7966 | I21: https://disclosure2.edinet-fsa.go.jp/WEEK0020.aspx | J21: https://www2.jpx.co.jp/tseHpFront/StockSearch.do?callJorEFlg=1&method=&topSearchStr=7966 | K21: Done | N21: N | O21: Y | P21: 7966.T | Q21: 72488740 | R21: 46022 | S21: 6991568 | T21: 46153 | U21: 0.6323 | V21: 6991568 | W21: 0.0965 | X21: 72488740 | Y21: 0.6321 | Z21: Y | AC21: Y | AD21: RT - Unchanged | AE21: 31-Dec-2025 | 11-May-2026 | AF21: 31-Dec-2025 | 11-May-2026 | AG21: 46062.396 | AH21: 46150 | AK21: 72488740 | AL21: 0.6321 | AM21: 0 | AN21: 0.00031630555
A22: Ezaki Glico Co. Ltd. | B22: JP3161200005 | G22: Fred | H22: 2206 | I22: https://disclosure2.edinet-fsa.go.jp/WEEK0020.aspx | J22: https://www2.jpx.co.jp/tseHpFront/StockSearch.do?callJorEFlg=1&method=&topSearchStr=2206 | K22: Done | N22: N | O22: Y | P22: 2206.T | Q22: 68468569 | R22: 46022 | S22: 5321917 | T22: 46112 | U22: 0.862 | V22: 5321917 | W22: 0.0777 | X22: 68468569 | Y22: 0.7787 | Z22: Y | AC22: Y | AD22: RT - Unchanged | AE22: 31-Dec-2025 | 31-Mar-2026 | AF22: 31-Dec-2025 | 31-Mar-2026 | AG22: 46066.5 | AH22: 46150 | AK22: 68468569 | AL22: 0.7787 | AM22: 0 | AN22: 0.096635731
A23: Denka Co Ltd | B23: JP3549600009 | G23: Fred | H23: 4061 | I23: https://disclosure2.edinet-fsa.go.jp/WEEK0020.aspx | J23: https://www2.jpx.co.jp/tseHpFront/StockSearch.do?callJorEFlg=1&method=&topSearchStr=4061 | K23: Done | N23: N | O23: N | P23: 4061.T | Q23: 88555840 | R23: 46022 | S23: 2355229 | T23: 46022 | U23: 1 | V23: 2355229 | W23: 0.0266 | X23: 88555840 | Y23: 1 | AD23: RT - Unchanged | AE23: 31-Dec-2025 | 31-Dec-2025 | AF23: 31-Dec-2025 | 31-Dec-2025 | AG23: 46059.312 | AH23: 46154 | AK23: 88555840 | AL23: 1 | AM23: 0 | AN23: 0
A24: SBI Holdings Inc. | B24: JP3436120004 | G24: Fred | H24: 8473 | I24: https://disclosure2.edinet-fsa.go.jp/WEEK0020.aspx | J24: https://www2.jpx.co.jp/tseHpFront/StockSearch.do?callJorEFlg=1&method=&topSearchStr=8473 | K24: Done | N24: Y | O24: N | P24: 8473.T | Q24: 661122614 | R24: 46112 | S24: 14760216 | T24: 46112 | U24: 0.8366 | V24: 14759996 | W24: 0.0223 | X24: 660847014 | Y24: 0.8366 | AB24: Y | AD24: RT - Unchanged | AE24: 31-Mar-2026 | 31-Mar-2026 | AF24: 31-Mar-2026 | 31-Mar-2026 | AG24: 46143.278 | AH24: 46235 | AK24: 660798614 | AL24: 0.8366 | AM24: 0.00049007551 | AN24: 0 | AO24: OK
A25: Square Enix Holdings Co. Ltd. | B25: JP3164630000 | G25: Fred | H25: 9684 | I25: https://disclosure2.edinet-fsa.go.jp/WEEK0020.aspx | J25: https://www2.jpx.co.jp/tseHpFront/StockSearch.do?callJorEFlg=1&method=&topSearchStr=9684 | K25: Done | N25: N | O25: Y | P25: 9684.T | Q25: 367594788 | R25: 46022 | S25: 6999293 | T25: 46022 | U25: 0.752 | V25: 6999293 | W25: 0.019 | X25: 367594788 | Y25: 0.752 | AD25: RT - Unchanged | AE25: 31-Dec-2025 | 31-Dec-2025 | AF25: 31-Dec-2025 | 31-Dec-2025 | AG25: 46058.5 | AH25: 46156 | AK25: 367594788 | AL25: 0.752 | AM25: 0 | AN25: 0
A26: Eisai Co. Ltd. | B26: JP3160400002 | G26: Fred | H26: 4523 | I26: https://disclosure2.edinet-fsa.go.jp/WEEK0020.aspx | J26: https://www2.jpx.co.jp/tseHpFront/StockSearch.do?callJorEFlg=1&method=&topSearchStr=4523 | K26: Done | N26: N | O26: N | P26: 4523.T | Q26: 291649149 | R26: 46022 | S26: 9534768 | T26: 46022 | U26: 1 | V26: 9534768 | W26: 0.0327 | X26: 291649149 | Y26: 1 | AD26: RT - Unchanged | AE26: 31-Dec-2025 | 31-Dec-2025 | AF26: 31-Dec-2025 | 31-Dec-2025 | AG26: 46062.5 | AH26: 46156 | AK26: 291649149 | AL26: 1 | AM26: 0 | AN26: 0
A27: Ebara Corp. | B27: JP3166000004 | G27: Fred | H27: 6361 | I27: https://disclosure2.edinet-fsa.go.jp/WEEK0020.aspx | J27: https://www2.jpx.co.jp/tseHpFront/StockSearch.do?callJorEFlg=1&method=&topSearchStr=6361 | K27: Done | N27: Y | O27: N | P27: 6361.T | Q27: 457262685 | R27: 46112 | S27: 268749 | T27: 46155 | U27: 1 | V27: 268749 | W27: 0.0006 | X27: 457199185 | Y27: 1 | AB27: Y | AD27: RT - Unchanged | AE27: 31-Mar-2026 | 13-May-2026 | AF27: 31-Mar-2026 | 13-May-2026 | AG27: 46066.5 | AH27: 46157 | AK27: 462195185 | AL27: 1 | AM27: 0.010787016 | AN27: 0
A28: East Japan Railway Co. | B28: JP3783600004 | G28: Fred | H28: 9020 | I28: https://disclosure2.edinet-fsa.go.jp/WEEK0020.aspx | J28: https://www2.jpx.co.jp/tseHpFront/StockSearch.do?callJorEFlg=1&method=&topSearchStr=9020 | K28: Done | N28: N | O28: N | P28: 9020.T | Q28: 1134412200 | R28: 46112 | S28: 5343717 | T28: 46112 | U28: 1 | V28: 5340272 | W28: 0.0047 | X28: 1134412200 | Y28: 1 | AD28: RT - Unchanged | AE28: 31-Mar-2026 | 31-Mar-2026 | AF28: 31-Mar-2026 | 31-Mar-2026 | AG28: 46142.503 | AH28: 46232 | AK28: 1134412200 | AL28: 1 | AM28: 0 | AN28: 0
A29: ABC-MART | B29: JP3152740001 | G29: Fred | H29: 2670 | I29: https://disclosure2.edinet-fsa.go.jp/WEEK0020.aspx | J29: https://www2.jpx.co.jp/tseHpFront/StockSearch.do?callJorEFlg=1&method=&topSearchStr=2670 | K29: Done | N29: N | O29: N | P29: 2670.T | Q29: 247618938 | R29: 46081 | S29: 2318 | T29: 46081 | U29: 0.4057 | V29: 2318 | W29: 0 | X29: 247618938 | Y29: 0.4057 | AD29: RT - Unchanged | AE29: 28-Feb-2026 | 28-Feb-2026 | AF29: 28-Feb-2026 | 28-Feb-2026 | AG29: 46120.5 | AH29: 46210 | AK29: 247618938 | AL29: 0.4057 | AM29: 0 | AN29: 0
A30: SKY PERFECT JSAT | B30: JP3396350005 | G30: Fred | H30: 9412 | I30: https://disclosure2.edinet-fsa.go.jp/WEEK0020.aspx | J30: https://www2.jpx.co.jp/tseHpFront/StockSearch.do?callJorEFlg=1&method=&topSearchStr=9412 | K30: Done | N30: N | O30: Y | P30: 9412.T | Q30: 297681264 | R30: 46112 | S30: 14202474 | T30: 46237 | U30: 0.5231 | V30: 14202474 | W30: 0.0477 | X30: 297681264 | Y30: 0.5077 | AC30: Y | AD30: RT - Unchanged | AE30: 31-Mar-2026 | 03-Aug-2026 | AF30: 31-Mar-2026 | 03-Aug-2026 | AG30: 46140.438 | AH30: 46238 | AK30: 297681264 | AL30: 0.5077 | AM30: 0 | AN30: 0.029439878
A31: TV ASAHI | B31: JP3429000007 | G31: Fred | H31: 9409 | I31: https://disclosure2.edinet-fsa.go.jp/WEEK0020.aspx | J31: https://www2.jpx.co.jp/tseHpFront/StockSearch.do?callJorEFlg=1&method=&topSearchStr=9409 | K31: Done | N31: N | O31: Y | P31: 9409.T | Q31: 108529000 | R31: 46022 | S31: 7989666 | T31: 46022 | U31: 0.5608 | V31: 7989666 | W31: 0.0736 | X31: 108529000 | Y31: 0.5604 | Z31: Y | AC31: Y | AD31: RT - Unchanged | AE31: 31-Dec-2025 | 31-Dec-2025 | AF31: 31-Dec-2025 | 31-Dec-2025 | AG31: 46065.562 | AH31: 46156 | AK31: 108529000 | AL31: 0.5604 | AM31: 0 | AN31: 0.00071326676
A32: DCM HOLDINGS | B32: JP3548660004 | G32: Fred | H32: 3050 | I32: https://disclosure2.edinet-fsa.go.jp/WEEK0020.aspx | J32: https://www2.jpx.co.jp/tseHpFront/StockSearch.do?callJorEFlg=1&method=&topSearchStr=3050 | K32: Done | N32: N | O32: Y | P32: 3050.T | Q32: 146500000 | R32: 46081 | S32: 9483608 | T32: 46142 | U32: 0.7807 | V32: 8847308 | W32: 0.0604 | X32: 146500000 | Y32: 0.7826 | Z32: Y | AA32: Y | AC32: Y | AD32: RT - Unchanged | AE32: 28-Feb-2026 | 30-Apr-2026 | AF32: 28-Feb-2026 | 30-Apr-2026 | AG32: 46126.5 | AH32: 46198 | AK32: 146500000 | AL32: 0.7826 | AM32: 0 | AN32: 0.0024337133
A33: Dowa Holdings Co. Ltd. | B33: JP3638600001 | G33: Fred | H33: 5714 | I33: https://disclosure2.edinet-fsa.go.jp/WEEK0020.aspx | J33: https://www2.jpx.co.jp/tseHpFront/StockSearch.do?callJorEFlg=1&method=&topSearchStr=5714 | K33: Done | N33: N | O33: N | P33: 5714.T | Q33: 61989206 | R33: 46022 | S33: 3438166 | T33: 46065 | U33: 0.9445 | V33: 3438166 | W33: 0.0555 | X33: 61989206 | Y33: 0.9445 | Z33: Y | AD33: RT - Unchanged | AE33: 31-Dec-2025 | 12-Feb-2026 | AF33: 31-Dec-2025 | 12-Feb-2026 | AG33: 46063.5 | AH33: 46156 | AK33: 61989206 | AL33: 0.9445 | AM33: 0 | AN33: 0
A34: NAKANISHI | B34: JP3642500007 | G34: Fred | H34: 7716 | I34: https://disclosure2.edinet-fsa.go.jp/WEEK0020.aspx | J34: https://www2.jpx.co.jp/tseHpFront/StockSearch.do?callJorEFlg=1&method=&topSearchStr=7716 | K34: Done | N34: N | O34: Y | P34: 7716.T | Q34: 92218200 | R34: 46052 | S34: 9168818 | T34: 46139 | U34: 0.9006 | V34: 9168818 | W34: 0.0994 | X34: 92218200 | Y34: 0.9005 | Z34: Y | AC34: Y | AD34: RT - Unchanged | AE34: 30-Jan-2026 | 27-Apr-2026 | AF34: 30-Jan-2026 | 27-Apr-2026 | AG34: 46065.5 | AH34: 46156 | AK34: 93418200 | AL34: 0.889 | AM34: 0.013012616 | AN34: 0.012880302
A35: Disco Corp. | B35: JP3548600000 | G35: Fred | H35: 6146 | I35: https://disclosure2.edinet-fsa.go.jp/WEEK0020.aspx | J35: https://www2.jpx.co.jp/tseHpFront/StockSearch.do?callJorEFlg=1&method=&topSearchStr=6146 | K35: Done | N35: N | O35: N | P35: 6146.T | Q35: 108478029 | R35: 46112 | S35: 16004 | T35: 46112 | U35: 0.8935 | V35: 16004 | W35: 0.0001 | X35: 108446529 | Y35: 0.8934 | AB35: Y | AC35: Y | AD35: RT - Unchanged | AE35: 31-Mar-2026 | 31-Mar-2026 | AF35: 31-Mar-2026 | 31-Mar-2026 | AG35: 46134.522 | AH35: 46225 | AK35: 108446529 | AL35: 0.8934 | AM35: 0.00029038138 | AN35: 0.00011191942
A36: PAN PACIFIC INTL HLDG | B36: JP3639650005 | G36: Fred | H36: 7532 | I36: https://disclosure2.edinet-fsa.go.jp/WEEK0020.aspx | J36: https://www2.jpx.co.jp/tseHpFront/StockSearch.do?callJorEFlg=1&method=&topSearchStr=7532 | K36: Done | N36: N | O36: Y | P36: 7532.T | Q36: 3177296700 | R36: 46022 | S36: 161678075 | T36: 46204 | U36: 0.634 | V36: 161678075 | W36: 0.0509 | X36: 3177296700 | Y36: 0.6251 | Z36: Y | AC36: Y | AD36: RT - Unchanged | AE36: 31-Dec-2025 | 01-Jul-2026 | AF36: 31-Dec-2025 | 01-Jul-2026 | AG36: 46065.5 | AH36: 46155 | AK36: 3177296700 | AL36: 0.6251 | AM36: 0 | AN36: 0.014037855
A37: MITSUBISHI HC CAPITAL | B37: JP3499800005 | G37: Fred | H37: 8593 | I37: https://disclosure2.edinet-fsa.go.jp/WEEK0020.aspx | J37: https://www2.jpx.co.jp/tseHpFront/StockSearch.do?callJorEFlg=1&method=&topSearchStr=8593 | K37: Done | N37: N | O37: N | P37: 8593.T | Q37: 1466912244 | R37: 46022 | S37: 31108080 | T37: 46022 | U37: 0.678 | V37: 31108080 | W37: 0.0212 | X37: 1466912244 | Y37: 0.678 | AD37: RT - Unchanged | AE37: 31-Dec-2025 | 31-Dec-2025 | AF37: 31-Dec-2025 | 31-Dec-2025 | AG37: 46066.5 | AH37: 46157 | AK37: 1466912244 | AL37: 0.678 | AM37: 0 | AN37: 0
A38: Otsuka Corp. | B38: JP3188200004 | G38: Fred | H38: 4768 | I38: https://disclosure2.edinet-fsa.go.jp/WEEK0020.aspx | J38: https://www2.jpx.co.jp/tseHpFront/StockSearch.do?callJorEFlg=1&method=&topSearchStr=4768 | K38: Done | N38: N | O38: N | P38: 4768.T | Q38: 380004240 | R38: 46112 | S38: 803061 | T38: 46112 | U38: 0.6653 | V38: 803041 | W38: 0.0021 | X38: 380004240 | Y38: 0.6653 | AD38: RT - Unchanged | AE38: 31-Mar-2026 | 31-Mar-2026 | AF38: 31-Mar-2026 | 31-Mar-2026 | AG38: 46142.503 | AH38: 46234 | AK38: 380004240 | AL38: 0.6653 | AM38: 0 | AN38: 0
A39: DAISEKI | B39: JP3485600005 | F39: tbd | G39: Fred | H39: 9793 | I39: https://disclosure2.edinet-fsa.go.jp/WEEK0020.aspx | J39: https://www2.jpx.co.jp/tseHpFront/StockSearch.do?callJorEFlg=1&method=&topSearchStr=9793 | K39: Done | N39: N | O39: N | P39: 9793.T | Q39: 48000000 | R39: 46081 | S39: 714476 | T39: 46081 | U39: 0.9463 | V39: 714476 | W39: 0.0149 | X39: 48000000 | Y39: 0.9462 | AC39: Y | AD39: RT - Unchanged | AE39: 28-Feb-2026 | 28-Feb-2026 | AF39: 28-Feb-2026 | 28-Feb-2026 | AG39: 46119.5 | AH39: 46203 | AK39: 48000000 | AL39: 0.9462 | AM39: 0 | AN39: 0.00010567473
A40: SUGI HOLDINGS | B40: JP3397060009 | G40: Fred | H40: 7649 | I40: https://disclosure2.edinet-fsa.go.jp/WEEK0020.aspx | J40: https://www2.jpx.co.jp/tseHpFront/StockSearch.do?callJorEFlg=1&method=&topSearchStr=7649 | K40: Done | N40: N | O40: N | P40: 7649.T | Q40: 379985028 | R40: 46262 | S40: 18039368 | T40: 46262 | U40: 0.8218 | V40: 18039368 | W40: 0.0475 | X40: 189992514 | Y40: 0.6435 | AB40: Y | AC40: Y | AD40: RT - Unchanged | AE40: 28-Aug-2026 | 28-Aug-2026 | AF40: 28-Aug-2026 | 28-Aug-2026 | AG40: 46121.5 | AH40: 46211 | AK40: 189992514 | AL40: 0.6435 | AM40: 0.5 | AN40: 0.21696276
...

Sheet Sheet2
A1: stock_code | B1: total_shares | C1: big_shareholders_pct
A2: 8334.T | B2: 395888177 | C2: 100 | D2: =LEFT(A2,4) -> 8334 | E2: =_xlfn.XLOOKUP(D2,Sheet1!H:H,Sheet1!Q:Q) -> 395888177 | F2: =_xlfn.XLOOKUP(D2,Sheet1!H:H,Sheet1!Y:Y)*100 -> 100 | G2: =IF(B2<>E2,"Y", "N") -> N | H2: =IF(C2<>F2,"Y", "N") -> N | J2: 8334 | K2: {=_xlfn.XLOOKUP(J2,D:D,G:H)} -> N | L2: N
A3: 4307.T | B3: 581241511 | C3: 80.09 | D3: =LEFT(A3,4) -> 4307 | E3: =_xlfn.XLOOKUP(D3,Sheet1!H:H,Sheet1!Q:Q) -> 581241511 | F3: =_xlfn.XLOOKUP(D3,Sheet1!H:H,Sheet1!Y:Y)*100 -> 80.09 | G3: =IF(B3<>E3,"Y", "N") -> N | H3: =IF(C3<>F3,"Y", "N") -> N | J3: 8952
A4: 2702.T | B4: 132960000 | C4: 64.68 | D4: =LEFT(A4,4) -> 2702 | E4: =_xlfn.XLOOKUP(D4,Sheet1!H:H,Sheet1!Q:Q) -> 132960000 | F4: =_xlfn.XLOOKUP(D4,Sheet1!H:H,Sheet1!Y:Y)*100 -> 64.68 | G4: =IF(B4<>E4,"Y", "N") -> N | H4: =IF(C4<>F4,"Y", "N") -> N | J4: 8951
A5: 5801.T | B5: 70666917 | C5: 100 | D5: =LEFT(A5,4) -> 5801 | E5: =_xlfn.XLOOKUP(D5,Sheet1!H:H,Sheet1!Q:Q) -> 70666917 | F5: =_xlfn.XLOOKUP(D5,Sheet1!H:H,Sheet1!Y:Y)*100 -> 100 | G5: =IF(B5<>E5,"Y", "N") -> N | H5: =IF(C5<>F5,"Y", "N") -> N | J5: 4307 | K5: {=_xlfn.XLOOKUP(J5,D:D,G:H)} -> N | L5: N
A6: 6960.T | B6: 37747300 | C6: 56.63 | D6: =LEFT(A6,4) -> 6960 | E6: =_xlfn.XLOOKUP(D6,Sheet1!H:H,Sheet1!Q:Q) -> 37747300 | F6: =_xlfn.XLOOKUP(D6,Sheet1!H:H,Sheet1!Y:Y)*100 -> 57.39 | G6: =IF(B6<>E6,"Y", "N") -> N | H6: =IF(C6<>F6,"Y", "N") -> Y | J6: 6457 | K6: {=_xlfn.XLOOKUP(J6,D:D,G:H)} -> N | L6: Y
A7: 6702.T | B7: 1739778265 | C7: 100 | D7: =LEFT(A7,4) -> 6702 | E7: =_xlfn.XLOOKUP(D7,Sheet1!H:H,Sheet1!Q:Q) -> 1739778265 | F7: =_xlfn.XLOOKUP(D7,Sheet1!H:H,Sheet1!Y:Y)*100 -> 84.35 | G7: =IF(B7<>E7,"Y", "N") -> N | H7: =IF(C7<>F7,"Y", "N") -> Y | J7: 2702 | K7: {=_xlfn.XLOOKUP(J7,D:D,G:H)} -> N | L7: N
A8: 2607.T | B8: 87569383 | C8: 58.14 | D8: =LEFT(A8,4) -> 2607 | E8: =_xlfn.XLOOKUP(D8,Sheet1!H:H,Sheet1!Q:Q) -> 87569383 | F8: =_xlfn.XLOOKUP(D8,Sheet1!H:H,Sheet1!Y:Y)*100 -> 58.14 | G8: =IF(B8<>E8,"Y", "N") -> N | H8: =IF(C8<>F8,"Y", "N") -> N | J8: 5801 | K8: {=_xlfn.XLOOKUP(J8,D:D,G:H)} -> N | L8: N
A9: 5803.T | B9: 1775180526 | C9: 93.26 | D9: =LEFT(A9,4) -> 5803 | E9: =_xlfn.XLOOKUP(D9,Sheet1!H:H,Sheet1!Q:Q) -> 1775180526 | F9: =_xlfn.XLOOKUP(D9,Sheet1!H:H,Sheet1!Y:Y)*100 -> 93.26 | G9: =IF(B9<>E9,"Y", "N") -> N | H9: =IF(C9<>F9,"Y", "N") -> N | J9: 6960 | K9: {=_xlfn.XLOOKUP(J9,D:D,G:H)} -> N | L9: Y
A10: 6134.T | B10: 97823748 | C10: 89.87 | D10: =LEFT(A10,4) -> 6134 | E10: =_xlfn.XLOOKUP(D10,Sheet1!H:H,Sheet1!Q:Q) -> 97823748 | F10: =_xlfn.XLOOKUP(D10,Sheet1!H:H,Sheet1!Y:Y)*100 -> 89.87 | G10: =IF(B10<>E10,"Y", "N") -> N | H10: =IF(C10<>F10,"Y", "N") -> N | J10: 6702 | K10: {=_xlfn.XLOOKUP(J10,D:D,G:H)} -> N | L10: Y
A11: 4901.T | B11: 1243877184 | C11: 100 | D11: =LEFT(A11,4) -> 4901 | E11: =_xlfn.XLOOKUP(D11,Sheet1!H:H,Sheet1!Q:Q) -> 1243877184 | F11: =_xlfn.XLOOKUP(D11,Sheet1!H:H,Sheet1!Y:Y)*100 -> 100 | G11: =IF(B11<>E11,"Y", "N") -> N | H11: =IF(C11<>F11,"Y", "N") -> N | J11: 6954 | K11: Y | L11: Y
A12: 7270.T | B12: 717335273 | C12: 78.59 | D12: =LEFT(A12,4) -> 7270 | E12: =_xlfn.XLOOKUP(D12,Sheet1!H:H,Sheet1!Q:Q) -> 717335273 | F12: =_xlfn.XLOOKUP(D12,Sheet1!H:H,Sheet1!Y:Y)*100 -> 78.59 | G12: =IF(B12<>E12,"Y", "N") -> N | H12: =IF(C12<>F12,"Y", "N") -> N | J12: 2607 | K12: {=_xlfn.XLOOKUP(J12,D:D,G:H)} -> N | L12: N
A13: 6504.T | B13: 149296991 | C13: 100 | D13: =LEFT(A13,4) -> 6504 | E13: =_xlfn.XLOOKUP(D13,Sheet1!H:H,Sheet1!Q:Q) -> 149296991 | F13: =_xlfn.XLOOKUP(D13,Sheet1!H:H,Sheet1!Y:Y)*100 -> 100 | G13: =IF(B13<>E13,"Y", "N") -> N | H13: =IF(C13<>F13,"Y", "N") -> N | J13: 5803 | K13: {=_xlfn.XLOOKUP(J13,D:D,G:H)} -> N | L13: N
A14: 8524.T | B14: 378060179 | C14: 93.85 | D14: =LEFT(A14,4) -> 8524 | E14: =_xlfn.XLOOKUP(D14,Sheet1!H:H,Sheet1!Q:Q) -> 378060179 | F14: =_xlfn.XLOOKUP(D14,Sheet1!H:H,Sheet1!Y:Y)*100 -> 94.17 | G14: =IF(B14<>E14,"Y", "N") -> N | H14: =IF(C14<>F14,"Y", "N") -> Y | J14: 4544 | K14: N | L14: N
A15: 9983.T | B15: 318220968 | C15: 79.84 | D15: =LEFT(A15,4) -> 9983 | E15: =_xlfn.XLOOKUP(D15,Sheet1!H:H,Sheet1!Q:Q) -> 318220968 | F15: =_xlfn.XLOOKUP(D15,Sheet1!H:H,Sheet1!Y:Y)*100 -> 78.8 | G15: =IF(B15<>E15,"Y", "N") -> N | H15: =IF(C15<>F15,"Y", "N") -> Y | J15: 6134 | K15: {=_xlfn.XLOOKUP(J15,D:D,G:H)} -> N | L15: N
A16: 7966.T | B16: 72488740 | C16: 63.23 | D16: =LEFT(A16,4) -> 7966 | E16: =_xlfn.XLOOKUP(D16,Sheet1!H:H,Sheet1!Q:Q) -> 72488740 | F16: =_xlfn.XLOOKUP(D16,Sheet1!H:H,Sheet1!Y:Y)*100 -> 63.21 | G16: =IF(B16<>E16,"Y", "N") -> N | H16: =IF(C16<>F16,"Y", "N") -> Y | J16: 4901 | K16: {=_xlfn.XLOOKUP(J16,D:D,G:H)} -> N | L16: N
A17: 2206.T | B17: 68468569 | C17: 86.2 | D17: =LEFT(A17,4) -> 2206 | E17: =_xlfn.XLOOKUP(D17,Sheet1!H:H,Sheet1!Q:Q) -> 68468569 | F17: =_xlfn.XLOOKUP(D17,Sheet1!H:H,Sheet1!Y:Y)*100 -> 77.87 | G17: =IF(B17<>E17,"Y", "N") -> N | H17: =IF(C17<>F17,"Y", "N") -> Y | J17: 7270 | K17: {=_xlfn.XLOOKUP(J17,D:D,G:H)} -> N | L17: N
A18: 4061.T | B18: 88555840 | C18: 100 | D18: =LEFT(A18,4) -> 4061 | E18: =_xlfn.XLOOKUP(D18,Sheet1!H:H,Sheet1!Q:Q) -> 88555840 | F18: =_xlfn.XLOOKUP(D18,Sheet1!H:H,Sheet1!Y:Y)*100 -> 100 | G18: =IF(B18<>E18,"Y", "N") -> N | H18: =IF(C18<>F18,"Y", "N") -> N | J18: 6504 | K18: {=_xlfn.XLOOKUP(J18,D:D,G:H)} -> N | L18: N
A19: 9684.T | B19: 367594788 | C19: 75.04 | D19: =LEFT(A19,4) -> 9684 | E19: =_xlfn.XLOOKUP(D19,Sheet1!H:H,Sheet1!Q:Q) -> 367594788 | F19: =_xlfn.XLOOKUP(D19,Sheet1!H:H,Sheet1!Y:Y)*100 -> 75.2 | G19: =IF(B19<>E19,"Y", "N") -> N | H19: =IF(C19<>F19,"Y", "N") -> Y | J19: 8524 | K19: {=_xlfn.XLOOKUP(J19,D:D,G:H)} -> N | L19: Y
A20: 4523.T | B20: 291649149 | C20: 100 | D20: =LEFT(A20,4) -> 4523 | E20: =_xlfn.XLOOKUP(D20,Sheet1!H:H,Sheet1!Q:Q) -> 291649149 | F20: =_xlfn.XLOOKUP(D20,Sheet1!H:H,Sheet1!Y:Y)*100 -> 100 | G20: =IF(B20<>E20,"Y", "N") -> N | H20: =IF(C20<>F20,"Y", "N") -> N | J20: 9983 | K20: {=_xlfn.XLOOKUP(J20,D:D,G:H)} -> N | L20: Y
A21: 6361.T | B21: 457199185 | C21: 100 | D21: =LEFT(A21,4) -> 6361 | E21: =_xlfn.XLOOKUP(D21,Sheet1!H:H,Sheet1!Q:Q) -> 457262685 | F21: =_xlfn.XLOOKUP(D21,Sheet1!H:H,Sheet1!Y:Y)*100 -> 100 | G21: =IF(B21<>E21,"Y", "N") -> Y | H21: =IF(C21<>F21,"Y", "N") -> N | J21: 7966 | K21: {=_xlfn.XLOOKUP(J21,D:D,G:H)} -> N | L21: Y
A22: 9020.T | B22: 1134412200 | C22: 100 | D22: =LEFT(A22,4) -> 9020 | E22: =_xlfn.XLOOKUP(D22,Sheet1!H:H,Sheet1!Q:Q) -> 1134412200 | F22: =_xlfn.XLOOKUP(D22,Sheet1!H:H,Sheet1!Y:Y)*100 -> 100 | G22: =IF(B22<>E22,"Y", "N") -> N | H22: =IF(C22<>F22,"Y", "N") -> N | J22: 2206 | K22: {=_xlfn.XLOOKUP(J22,D:D,G:H)} -> N | L22: Y
A23: 2670.T | B23: 247618938 | C23: 40.57 | D23: =LEFT(A23,4) -> 2670 | E23: =_xlfn.XLOOKUP(D23,Sheet1!H:H,Sheet1!Q:Q) -> 247618938 | F23: =_xlfn.XLOOKUP(D23,Sheet1!H:H,Sheet1!Y:Y)*100 -> 40.57 | G23: =IF(B23<>E23,"Y", "N") -> N | H23: =IF(C23<>F23,"Y", "N") -> N | J23: 4061 | K23: {=_xlfn.XLOOKUP(J23,D:D,G:H)} -> N | L23: N
A24: 9412.T | B24: 297681264 | C24: 52.32 | D24: =LEFT(A24,4) -> 9412 | E24: =_xlfn.XLOOKUP(D24,Sheet1!H:H,Sheet1!Q:Q) -> 297681264 | F24: =_xlfn.XLOOKUP(D24,Sheet1!H:H,Sheet1!Y:Y)*100 -> 50.77 | G24: =IF(B24<>E24,"Y", "N") -> N | H24: =IF(C24<>F24,"Y", "N") -> Y | J24: 8473 | K24: Y | L24: N
A25: 9409.T | B25: 108529000 | C25: 56.08 | D25: =LEFT(A25,4) -> 9409 | E25: =_xlfn.XLOOKUP(D25,Sheet1!H:H,Sheet1!Q:Q) -> 108529000 | F25: =_xlfn.XLOOKUP(D25,Sheet1!H:H,Sheet1!Y:Y)*100 -> 56.04 | G25: =IF(B25<>E25,"Y", "N") -> N | H25: =IF(C25<>F25,"Y", "N") -> Y | J25: 9684 | K25: {=_xlfn.XLOOKUP(J25,D:D,G:H)} -> N | L25: Y
A26: 3050.T | B26: 146500000 | C26: 78.08 | D26: =LEFT(A26,4) -> 3050 | E26: =_xlfn.XLOOKUP(D26,Sheet1!H:H,Sheet1!Q:Q) -> 146500000 | F26: =_xlfn.XLOOKUP(D26,Sheet1!H:H,Sheet1!Y:Y)*100 -> 78.26 | G26: =IF(B26<>E26,"Y", "N") -> N | H26: =IF(C26<>F26,"Y", "N") -> Y | J26: 4523 | K26: {=_xlfn.XLOOKUP(J26,D:D,G:H)} -> N | L26: N
A27: 5714.T | B27: 61989206 | C27: 94.45 | D27: =LEFT(A27,4) -> 5714 | E27: =_xlfn.XLOOKUP(D27,Sheet1!H:H,Sheet1!Q:Q) -> 61989206 | F27: =_xlfn.XLOOKUP(D27,Sheet1!H:H,Sheet1!Y:Y)*100 -> 94.45 | G27: =IF(B27<>E27,"Y", "N") -> N | H27: =IF(C27<>F27,"Y", "N") -> N | J27: 6361 | K27: {=_xlfn.XLOOKUP(J27,D:D,G:H)} -> Y | L27: N
A28: 7716.T | B28: 92218200 | C28: 90.06 | D28: =LEFT(A28,4) -> 7716 | E28: =_xlfn.XLOOKUP(D28,Sheet1!H:H,Sheet1!Q:Q) -> 92218200 | F28: =_xlfn.XLOOKUP(D28,Sheet1!H:H,Sheet1!Y:Y)*100 -> 90.05 | G28: =IF(B28<>E28,"Y", "N") -> N | H28: =IF(C28<>F28,"Y", "N") -> Y | J28: 9020 | K28: {=_xlfn.XLOOKUP(J28,D:D,G:H)} -> N | L28: N
A29: 6146.T | B29: 108478029 | C29: 89.34 | D29: =LEFT(A29,4) -> 6146 | E29: =_xlfn.XLOOKUP(D29,Sheet1!H:H,Sheet1!Q:Q) -> 108478029 | F29: =_xlfn.XLOOKUP(D29,Sheet1!H:H,Sheet1!Y:Y)*100 -> 89.34 | G29: =IF(B29<>E29,"Y", "N") -> N | H29: =IF(C29<>F29,"Y", "N") -> N | J29: 2670 | K29: {=_xlfn.XLOOKUP(J29,D:D,G:H)} -> N | L29: N
A30: 7532.T | B30: 3177296700 | C30: 62.56 | D30: =LEFT(A30,4) -> 7532 | E30: =_xlfn.XLOOKUP(D30,Sheet1!H:H,Sheet1!Q:Q) -> 3177296700 | F30: =_xlfn.XLOOKUP(D30,Sheet1!H:H,Sheet1!Y:Y)*100 -> 62.51 | G30: =IF(B30<>E30,"Y", "N") -> N | H30: =IF(C30<>F30,"Y", "N") -> Y | J30: 9412 | K30: {=_xlfn.XLOOKUP(J30,D:D,G:H)} -> N | L30: Y
A31: 8593.T | B31: 1466912244 | C31: 67.8 | D31: =LEFT(A31,4) -> 8593 | E31: =_xlfn.XLOOKUP(D31,Sheet1!H:H,Sheet1!Q:Q) -> 1466912244 | F31: =_xlfn.XLOOKUP(D31,Sheet1!H:H,Sheet1!Y:Y)*100 -> 67.8 | G31: =IF(B31<>E31,"Y", "N") -> N | H31: =IF(C31<>F31,"Y", "N") -> N | J31: 9409 | K31: {=_xlfn.XLOOKUP(J31,D:D,G:H)} -> N | L31: Y
A32: 4768.T | B32: 380004240 | C32: 66.53 | D32: =LEFT(A32,4) -> 4768 | E32: =_xlfn.XLOOKUP(D32,Sheet1!H:H,Sheet1!Q:Q) -> 380004240 | F32: =_xlfn.XLOOKUP(D32,Sheet1!H:H,Sheet1!Y:Y)*100 -> 66.53 | G32: =IF(B32<>E32,"Y", "N") -> N | H32: =IF(C32<>F32,"Y", "N") -> N | J32: 3050 | K32: {=_xlfn.XLOOKUP(J32,D:D,G:H)} -> N | L32: Y
A33: 9793.T | B33: 48000000 | C33: 94.62 | D33: =LEFT(A33,4) -> 9793 | E33: =_xlfn.XLOOKUP(D33,Sheet1!H:H,Sheet1!Q:Q) -> 48000000 | F33: =_xlfn.XLOOKUP(D33,Sheet1!H:H,Sheet1!Y:Y)*100 -> 94.62 | G33: =IF(B33<>E33,"Y", "N") -> N | H33: =IF(C33<>F33,"Y", "N") -> N | J33: 5714 | K33: {=_xlfn.XLOOKUP(J33,D:D,G:H)} -> N | L33: N
A34: 9682.T | B34: 163954928 | C34: 92.76 | D34: =LEFT(A34,4) -> 9682 | E34: =_xlfn.XLOOKUP(D34,Sheet1!H:H,Sheet1!Q:Q) -> 163954928 | F34: =_xlfn.XLOOKUP(D34,Sheet1!H:H,Sheet1!Y:Y)*100 -> 92.76 | G34: =IF(B34<>E34,"Y", "N") -> N | H34: =IF(C34<>F34,"Y", "N") -> N | J34: 7716 | K34: {=_xlfn.XLOOKUP(J34,D:D,G:H)} -> N | L34: Y
A35: 8601.T | B35: 1569378772 | C35: 88.29 | D35: =LEFT(A35,4) -> 8601 | E35: =_xlfn.XLOOKUP(D35,Sheet1!H:H,Sheet1!Q:Q) -> 1569378772 | F35: =_xlfn.XLOOKUP(D35,Sheet1!H:H,Sheet1!Y:Y)*100 -> 88 | G35: =IF(B35<>E35,"Y", "N") -> N | H35: =IF(C35<>F35,"Y", "N") -> Y | J35: 6146 | K35: {=_xlfn.XLOOKUP(J35,D:D,G:H)} -> N | L35: N
A36: 3107.T | B36: 88479028 | C36: 100 | D36: =LEFT(A36,4) -> 3107 | E36: =_xlfn.XLOOKUP(D36,Sheet1!H:H,Sheet1!Q:Q) -> 88479028 | F36: =_xlfn.XLOOKUP(D36,Sheet1!H:H,Sheet1!Y:Y)*100 -> 100 | G36: =IF(B36<>E36,"Y", "N") -> N | H36: =IF(C36<>F36,"Y", "N") -> N | J36: 7532 | K36: {=_xlfn.XLOOKUP(J36,D:D,G:H)} -> N | L36: Y
... A39: 7327.T | B39: 275657868 | C39: 100 | D39: =LEFT(A39,4) -> 7327 | E39: =_xlfn.XLOOKUP(D39,Sheet1!H:H,Sheet1!Q:Q) -> 275657868 | F39: =_xlfn.XLOOKUP(D39,Sheet1!H:H,Sheet1!Y:Y)*100 -> 100 | G39: =IF(B39<>E39,"Y", "N") -> N | H39: =IF(C39<>F39,"Y", "N") -> N | J39: 9793 | K39: {=_xlfn.XLOOKUP(J39,D:D,G:H)} -> N | L39: N
A40: 7735.T | B40: 190759972 | C40: 100 | D40: =LEFT(A40,4) -> 7735 | E40: =_xlfn.XLOOKUP(D40,Sheet1!H:H,Sheet1!Q:Q) -> 190759972 | F40: =_xlfn.XLOOKUP(D40,Sheet1!H:H,Sheet1!Y:Y)*100 -> 100 | G40: =IF(B40<>E40,"Y", "N") -> N | H40: =IF(C40<>F40,"Y", "N") -> N | J40: 7649 | K40: N | L40: N
A41: 7912.T | B41: 439480692 | C41: 100 | D41: =LEFT(A41,4) -> 7912 | E41: =_xlfn.XLOOKUP(D41,Sheet1!H:H,Sheet1!Q:Q) -> 439480692 | F41: =_xlfn.XLOOKUP(D41,Sheet1!H:H,Sheet1!Y:Y)*100 -> 82.71 | G41: =IF(B41<>E41,"Y", "N") -> N | H41: =IF(C41<>F41,"Y", "N") -> Y | J41: 9682 | K41: {=_xlfn.XLOOKUP(J41,D:D,G:H)} -> N | L41: N
A42: 4506.T | B42: 456900154 | C42: 54.99 | D42: =LEFT(A42,4) -> 4506 | E42: =_xlfn.XLOOKUP(D42,Sheet1!H:H,Sheet1!Q:Q) -> 456900154 | F42: =_xlfn.XLOOKUP(D42,Sheet1!H:H,Sheet1!Y:Y)*100 -> 48.32 | G42: =IF(B42<>E42,"Y", "N") -> N | H42: =IF(C42<>F42,"Y", "N") -> Y | J42: 8601 | K42: {=_xlfn.XLOOKUP(J42,D:D,G:H)} -> N | L42: Y
...
